*** Starting uWSGI 2.0.19.1 (64bit) on [Mon May 24 22:28:12 2021] ***
compiled with version: 7.5.0 on 24 May 2021 22:26:27
os: Linux-5.4.0-1048-aws #50~18.04.1-Ubuntu SMP Tue May 4 17:40:02 UTC 2021
nodename: ip-172-31-38-43
machine: x86_64
clock source: unix
pcre jit disabled
detected number of CPU cores: 1
current working directory: /home/ubuntu/Desktop/mydjweb
writing pidfile to /tmp/project-master.pid
detected binary path: /home/ubuntu/Desktop/venv/bin/uwsgi
chdir() to /home/ubuntu/Desktop/mydjweb
your processes number limit is 3800
your memory page size is 4096 bytes
detected max file descriptor number: 8192
lock engine: pthread robust mutexes
thunder lock: disabled (you can enable it with --thunder-lock)
uwsgi socket 0 bound to UNIX address /home/ubuntu/Desktop/mydjweb/uwsgi.sock fd 3
Python version: 3.6.9 (default, Jan 26 2021, 15:33:00)  [GCC 8.4.0]
PEP 405 virtualenv detected: /home/ubuntu/Desktop/venv
Set PythonHome to /home/ubuntu/Desktop/venv
*** Python threads support is disabled. You can enable it with --enable-threads ***
Python main interpreter initialized at 0x5619e011dd10
your server socket listen backlog is limited to 100 connections
your mercy for graceful operations on workers is 60 seconds
mapped 145840 bytes (142 KB) for 1 cores
*** Operational MODE: single process ***
WSGI app 0 (mountpoint='') ready in 1 seconds on interpreter 0x5619e011dd10 pid: 2451 (default app)
*** uWSGI is running in multiple interpreter mode ***
spawned uWSGI master process (pid: 2451)
spawned uWSGI worker 1 (pid: 2453, cores: 1)
[pid: 2453|app: 0|req: 1/1] 110.70.58.200 () {44 vars in 895 bytes} [Mon May 24 22:46:31 2021] GET / => generated 10697 bytes in 19 msecs (HTTP/1.1 200) 5 headers in 153 bytes (1 switches on core 0)
Not Found: /favicon.ico
[pid: 2453|app: 0|req: 2/2] 110.70.58.200 () {46 vars in 870 bytes} [Mon May 24 22:46:32 2021] GET /favicon.ico => generated 2110 bytes in 7 msecs (HTTP/1.1 404) 5 headers in 159 bytes (2 switches on core 0)
[pid: 2453|app: 0|req: 3/3] 110.70.58.200 () {42 vars in 864 bytes} [Mon May 24 23:00:18 2021] GET / => generated 10697 bytes in 4 msecs (HTTP/1.1 200) 5 headers in 153 bytes (1 switches on core 0)
*** Starting uWSGI 2.0.19.1 (64bit) on [Mon May 24 23:00:34 2021] ***
compiled with version: 7.5.0 on 24 May 2021 22:26:27
os: Linux-5.4.0-1048-aws #50~18.04.1-Ubuntu SMP Tue May 4 17:40:02 UTC 2021
nodename: ip-172-31-38-43
machine: x86_64
clock source: unix
pcre jit disabled
detected number of CPU cores: 1
current working directory: /home/ubuntu/Desktop/mydjweb
writing pidfile to /tmp/project-master.pid
detected binary path: /home/ubuntu/Desktop/venv/bin/uwsgi
chdir() to /home/ubuntu/Desktop/mydjweb
your processes number limit is 3800
your memory page size is 4096 bytes
detected max file descriptor number: 8192
lock engine: pthread robust mutexes
thunder lock: disabled (you can enable it with --thunder-lock)
uwsgi socket 0 bound to UNIX address /home/ubuntu/Desktop/mydjweb/uwsgi.sock fd 3
Python version: 3.6.9 (default, Jan 26 2021, 15:33:00)  [GCC 8.4.0]
PEP 405 virtualenv detected: /home/ubuntu/Desktop/venv
Set PythonHome to /home/ubuntu/Desktop/venv
*** Python threads support is disabled. You can enable it with --enable-threads ***
Python main interpreter initialized at 0x5654f586dd10
your server socket listen backlog is limited to 100 connections
your mercy for graceful operations on workers is 60 seconds
mapped 145840 bytes (142 KB) for 1 cores
*** Operational MODE: single process ***
WSGI app 0 (mountpoint='') ready in 0 seconds on interpreter 0x5654f586dd10 pid: 3124 (default app)
*** uWSGI is running in multiple interpreter mode ***
spawned uWSGI master process (pid: 3124)
spawned uWSGI worker 1 (pid: 3126, cores: 1)
Unnamed: 0     0
country        0
description    0
designation    0
points         0
price          0
province       0
region_1       0
region_2       0
variety        0
winery         0
dtype: int64
Internal Server Error: /
Traceback (most recent call last):
  File "/home/ubuntu/Desktop/venv/lib/python3.6/site-packages/django/db/backends/utils.py", line 84, in _execute
    return self.cursor.execute(sql, params)
  File "/home/ubuntu/Desktop/venv/lib/python3.6/site-packages/django/db/backends/sqlite3/base.py", line 423, in execute
    return Database.Cursor.execute(self, query, params)
sqlite3.OperationalError: no such table: main_coffee

The above exception was the direct cause of the following exception:

Traceback (most recent call last):
  File "/home/ubuntu/Desktop/venv/lib/python3.6/site-packages/django/core/handlers/exception.py", line 47, in inner
    response = get_response(request)
  File "/home/ubuntu/Desktop/venv/lib/python3.6/site-packages/django/core/handlers/base.py", line 181, in _get_response
    response = wrapped_callback(request, *callback_args, **callback_kwargs)
  File "./main/views.py", line 66, in main
    return render(request,"index.html", {"coffee_list":coffee_DB, "coffee_form":coffeeform,'plot_div': plot_div,'plot_div2':plot_div2,})
  File "/home/ubuntu/Desktop/venv/lib/python3.6/site-packages/django/shortcuts.py", line 19, in render
    content = loader.render_to_string(template_name, context, request, using=using)
  File "/home/ubuntu/Desktop/venv/lib/python3.6/site-packages/django/template/loader.py", line 62, in render_to_string
    return template.render(context, request)
  File "/home/ubuntu/Desktop/venv/lib/python3.6/site-packages/django/template/backends/django.py", line 61, in render
    return self.template.render(context)
  File "/home/ubuntu/Desktop/venv/lib/python3.6/site-packages/django/template/base.py", line 170, in render
    return self._render(context)
  File "/home/ubuntu/Desktop/venv/lib/python3.6/site-packages/django/template/base.py", line 162, in _render
    return self.nodelist.render(context)
  File "/home/ubuntu/Desktop/venv/lib/python3.6/site-packages/django/template/base.py", line 938, in render
    bit = node.render_annotated(context)
  File "/home/ubuntu/Desktop/venv/lib/python3.6/site-packages/django/template/base.py", line 905, in render_annotated
    return self.render(context)
  File "/home/ubuntu/Desktop/venv/lib/python3.6/site-packages/django/template/defaulttags.py", line 168, in render
    len_values = len(values)
  File "/home/ubuntu/Desktop/venv/lib/python3.6/site-packages/django/db/models/query.py", line 262, in __len__
    self._fetch_all()
  File "/home/ubuntu/Desktop/venv/lib/python3.6/site-packages/django/db/models/query.py", line 1324, in _fetch_all
    self._result_cache = list(self._iterable_class(self))
  File "/home/ubuntu/Desktop/venv/lib/python3.6/site-packages/django/db/models/query.py", line 51, in __iter__
    results = compiler.execute_sql(chunked_fetch=self.chunked_fetch, chunk_size=self.chunk_size)
  File "/home/ubuntu/Desktop/venv/lib/python3.6/site-packages/django/db/models/sql/compiler.py", line 1175, in execute_sql
    cursor.execute(sql, params)
  File "/home/ubuntu/Desktop/venv/lib/python3.6/site-packages/django/db/backends/utils.py", line 98, in execute
    return super().execute(sql, params)
  File "/home/ubuntu/Desktop/venv/lib/python3.6/site-packages/django/db/backends/utils.py", line 66, in execute
    return self._execute_with_wrappers(sql, params, many=False, executor=self._execute)
  File "/home/ubuntu/Desktop/venv/lib/python3.6/site-packages/django/db/backends/utils.py", line 75, in _execute_with_wrappers
    return executor(sql, params, many, context)
  File "/home/ubuntu/Desktop/venv/lib/python3.6/site-packages/django/db/backends/utils.py", line 84, in _execute
    return self.cursor.execute(sql, params)
  File "/home/ubuntu/Desktop/venv/lib/python3.6/site-packages/django/db/utils.py", line 90, in __exit__
    raise dj_exc_value.with_traceback(traceback) from exc_value
  File "/home/ubuntu/Desktop/venv/lib/python3.6/site-packages/django/db/backends/utils.py", line 84, in _execute
    return self.cursor.execute(sql, params)
  File "/home/ubuntu/Desktop/venv/lib/python3.6/site-packages/django/db/backends/sqlite3/base.py", line 423, in execute
    return Database.Cursor.execute(self, query, params)
django.db.utils.OperationalError: no such table: main_coffee
[pid: 3126|app: 0|req: 1/1] 110.70.58.200 () {44 vars in 895 bytes} [Mon May 24 23:00:46 2021] GET / => generated 161574 bytes in 2995 msecs (HTTP/1.1 500) 7 headers in 286 bytes (1 switches on core 0)
[pid: 3126|app: 0|req: 2/2] 110.70.58.200 () {42 vars in 830 bytes} [Mon May 24 23:01:04 2021] GET /admin => generated 0 bytes in 1 msecs (HTTP/1.1 301) 5 headers in 175 bytes (1 switches on core 0)
[pid: 3126|app: 0|req: 3/3] 110.70.58.200 () {42 vars in 832 bytes} [Mon May 24 23:01:04 2021] GET /admin/ => generated 0 bytes in 16 msecs (HTTP/1.1 302) 9 headers in 331 bytes (1 switches on core 0)
[pid: 3126|app: 0|req: 4/4] 110.70.58.200 () {42 vars in 869 bytes} [Mon May 24 23:01:04 2021] GET /admin/login/?next=/admin/ => generated 2214 bytes in 35 msecs (HTTP/1.1 200) 9 headers in 461 bytes (1 switches on core 0)
[pid: 3126|app: 0|req: 5/5] 110.70.58.200 () {52 vars in 1114 bytes} [Mon May 24 23:01:11 2021] POST /admin/login/?next=/admin/ => generated 0 bytes in 194 msecs (HTTP/1.1 302) 11 headers in 625 bytes (1 switches on core 0)
[pid: 3126|app: 0|req: 6/6] 110.70.58.200 () {46 vars in 969 bytes} [Mon May 24 23:01:11 2021] GET /admin/ => generated 3967 bytes in 25 msecs (HTTP/1.1 200) 8 headers in 293 bytes (1 switches on core 0)
[pid: 3126|app: 0|req: 7/7] 110.70.58.200 () {44 vars in 951 bytes} [Mon May 24 23:01:14 2021] GET /admin/main/coffee/add/ => generated 6075 bytes in 45 msecs (HTTP/1.1 200) 9 headers in 461 bytes (2 switches on core 0)
[pid: 3126|app: 0|req: 8/8] 110.70.58.200 () {42 vars in 782 bytes} [Mon May 24 23:01:14 2021] GET /admin/jsi18n/ => generated 3195 bytes in 8 msecs (HTTP/1.1 200) 6 headers in 189 bytes (1 switches on core 0)
Internal Server Error: /admin/main/coffee/add/
Traceback (most recent call last):
  File "/home/ubuntu/Desktop/venv/lib/python3.6/site-packages/django/db/backends/utils.py", line 84, in _execute
    return self.cursor.execute(sql, params)
  File "/home/ubuntu/Desktop/venv/lib/python3.6/site-packages/django/db/backends/sqlite3/base.py", line 423, in execute
    return Database.Cursor.execute(self, query, params)
sqlite3.OperationalError: no such table: main_coffee

The above exception was the direct cause of the following exception:

Traceback (most recent call last):
  File "/home/ubuntu/Desktop/venv/lib/python3.6/site-packages/django/core/handlers/exception.py", line 47, in inner
    response = get_response(request)
  File "/home/ubuntu/Desktop/venv/lib/python3.6/site-packages/django/core/handlers/base.py", line 181, in _get_response
    response = wrapped_callback(request, *callback_args, **callback_kwargs)
  File "/home/ubuntu/Desktop/venv/lib/python3.6/site-packages/django/contrib/admin/options.py", line 616, in wrapper
    return self.admin_site.admin_view(view)(*args, **kwargs)
  File "/home/ubuntu/Desktop/venv/lib/python3.6/site-packages/django/utils/decorators.py", line 130, in _wrapped_view
    response = view_func(request, *args, **kwargs)
  File "/home/ubuntu/Desktop/venv/lib/python3.6/site-packages/django/views/decorators/cache.py", line 44, in _wrapped_view_func
    response = view_func(request, *args, **kwargs)
  File "/home/ubuntu/Desktop/venv/lib/python3.6/site-packages/django/contrib/admin/sites.py", line 232, in inner
    return view(request, *args, **kwargs)
  File "/home/ubuntu/Desktop/venv/lib/python3.6/site-packages/django/contrib/admin/options.py", line 1657, in add_view
    return self.changeform_view(request, None, form_url, extra_context)
  File "/home/ubuntu/Desktop/venv/lib/python3.6/site-packages/django/utils/decorators.py", line 43, in _wrapper
    return bound_method(*args, **kwargs)
  File "/home/ubuntu/Desktop/venv/lib/python3.6/site-packages/django/utils/decorators.py", line 130, in _wrapped_view
    response = view_func(request, *args, **kwargs)
  File "/home/ubuntu/Desktop/venv/lib/python3.6/site-packages/django/contrib/admin/options.py", line 1540, in changeform_view
    return self._changeform_view(request, object_id, form_url, extra_context)
  File "/home/ubuntu/Desktop/venv/lib/python3.6/site-packages/django/contrib/admin/options.py", line 1579, in _changeform_view
    form_validated = form.is_valid()
  File "/home/ubuntu/Desktop/venv/lib/python3.6/site-packages/django/forms/forms.py", line 175, in is_valid
    return self.is_bound and not self.errors
  File "/home/ubuntu/Desktop/venv/lib/python3.6/site-packages/django/forms/forms.py", line 170, in errors
    self.full_clean()
  File "/home/ubuntu/Desktop/venv/lib/python3.6/site-packages/django/forms/forms.py", line 374, in full_clean
    self._post_clean()
  File "/home/ubuntu/Desktop/venv/lib/python3.6/site-packages/django/forms/models.py", line 419, in _post_clean
    self.validate_unique()
  File "/home/ubuntu/Desktop/venv/lib/python3.6/site-packages/django/forms/models.py", line 428, in validate_unique
    self.instance.validate_unique(exclude=exclude)
  File "/home/ubuntu/Desktop/venv/lib/python3.6/site-packages/django/db/models/base.py", line 1016, in validate_unique
    errors = self._perform_unique_checks(unique_checks)
  File "/home/ubuntu/Desktop/venv/lib/python3.6/site-packages/django/db/models/base.py", line 1119, in _perform_unique_checks
    if qs.exists():
  File "/home/ubuntu/Desktop/venv/lib/python3.6/site-packages/django/db/models/query.py", line 808, in exists
    return self.query.has_results(using=self.db)
  File "/home/ubuntu/Desktop/venv/lib/python3.6/site-packages/django/db/models/sql/query.py", line 550, in has_results
    return compiler.has_results()
  File "/home/ubuntu/Desktop/venv/lib/python3.6/site-packages/django/db/models/sql/compiler.py", line 1145, in has_results
    return bool(self.execute_sql(SINGLE))
  File "/home/ubuntu/Desktop/venv/lib/python3.6/site-packages/django/db/models/sql/compiler.py", line 1175, in execute_sql
    cursor.execute(sql, params)
  File "/home/ubuntu/Desktop/venv/lib/python3.6/site-packages/django/db/backends/utils.py", line 98, in execute
    return super().execute(sql, params)
  File "/home/ubuntu/Desktop/venv/lib/python3.6/site-packages/django/db/backends/utils.py", line 66, in execute
    return self._execute_with_wrappers(sql, params, many=False, executor=self._execute)
  File "/home/ubuntu/Desktop/venv/lib/python3.6/site-packages/django/db/backends/utils.py", line 75, in _execute_with_wrappers
    return executor(sql, params, many, context)
  File "/home/ubuntu/Desktop/venv/lib/python3.6/site-packages/django/db/backends/utils.py", line 84, in _execute
    return self.cursor.execute(sql, params)
  File "/home/ubuntu/Desktop/venv/lib/python3.6/site-packages/django/db/utils.py", line 90, in __exit__
    raise dj_exc_value.with_traceback(traceback) from exc_value
  File "/home/ubuntu/Desktop/venv/lib/python3.6/site-packages/django/db/backends/utils.py", line 84, in _execute
    return self.cursor.execute(sql, params)
  File "/home/ubuntu/Desktop/venv/lib/python3.6/site-packages/django/db/backends/sqlite3/base.py", line 423, in execute
    return Database.Cursor.execute(self, query, params)
django.db.utils.OperationalError: no such table: main_coffee
[pid: 3126|app: 0|req: 9/9] 110.70.58.200 () {52 vars in 1150 bytes} [Mon May 24 23:01:17 2021] POST /admin/main/coffee/add/ => generated 184823 bytes in 87 msecs (HTTP/1.1 500) 6 headers in 187 bytes (1 switches on core 0)
Internal Server Error: /admin/main/coffee/add/
Traceback (most recent call last):
  File "/home/ubuntu/Desktop/venv/lib/python3.6/site-packages/django/db/backends/utils.py", line 84, in _execute
    return self.cursor.execute(sql, params)
  File "/home/ubuntu/Desktop/venv/lib/python3.6/site-packages/django/db/backends/sqlite3/base.py", line 423, in execute
    return Database.Cursor.execute(self, query, params)
sqlite3.OperationalError: no such table: main_coffee

The above exception was the direct cause of the following exception:

Traceback (most recent call last):
  File "/home/ubuntu/Desktop/venv/lib/python3.6/site-packages/django/core/handlers/exception.py", line 47, in inner
    response = get_response(request)
  File "/home/ubuntu/Desktop/venv/lib/python3.6/site-packages/django/core/handlers/base.py", line 181, in _get_response
    response = wrapped_callback(request, *callback_args, **callback_kwargs)
  File "/home/ubuntu/Desktop/venv/lib/python3.6/site-packages/django/contrib/admin/options.py", line 616, in wrapper
    return self.admin_site.admin_view(view)(*args, **kwargs)
  File "/home/ubuntu/Desktop/venv/lib/python3.6/site-packages/django/utils/decorators.py", line 130, in _wrapped_view
    response = view_func(request, *args, **kwargs)
  File "/home/ubuntu/Desktop/venv/lib/python3.6/site-packages/django/views/decorators/cache.py", line 44, in _wrapped_view_func
    response = view_func(request, *args, **kwargs)
  File "/home/ubuntu/Desktop/venv/lib/python3.6/site-packages/django/contrib/admin/sites.py", line 232, in inner
    return view(request, *args, **kwargs)
  File "/home/ubuntu/Desktop/venv/lib/python3.6/site-packages/django/contrib/admin/options.py", line 1657, in add_view
    return self.changeform_view(request, None, form_url, extra_context)
  File "/home/ubuntu/Desktop/venv/lib/python3.6/site-packages/django/utils/decorators.py", line 43, in _wrapper
    return bound_method(*args, **kwargs)
  File "/home/ubuntu/Desktop/venv/lib/python3.6/site-packages/django/utils/decorators.py", line 130, in _wrapped_view
    response = view_func(request, *args, **kwargs)
  File "/home/ubuntu/Desktop/venv/lib/python3.6/site-packages/django/contrib/admin/options.py", line 1540, in changeform_view
    return self._changeform_view(request, object_id, form_url, extra_context)
  File "/home/ubuntu/Desktop/venv/lib/python3.6/site-packages/django/contrib/admin/options.py", line 1579, in _changeform_view
    form_validated = form.is_valid()
  File "/home/ubuntu/Desktop/venv/lib/python3.6/site-packages/django/forms/forms.py", line 175, in is_valid
    return self.is_bound and not self.errors
  File "/home/ubuntu/Desktop/venv/lib/python3.6/site-packages/django/forms/forms.py", line 170, in errors
    self.full_clean()
  File "/home/ubuntu/Desktop/venv/lib/python3.6/site-packages/django/forms/forms.py", line 374, in full_clean
    self._post_clean()
  File "/home/ubuntu/Desktop/venv/lib/python3.6/site-packages/django/forms/models.py", line 419, in _post_clean
    self.validate_unique()
  File "/home/ubuntu/Desktop/venv/lib/python3.6/site-packages/django/forms/models.py", line 428, in validate_unique
    self.instance.validate_unique(exclude=exclude)
  File "/home/ubuntu/Desktop/venv/lib/python3.6/site-packages/django/db/models/base.py", line 1016, in validate_unique
    errors = self._perform_unique_checks(unique_checks)
  File "/home/ubuntu/Desktop/venv/lib/python3.6/site-packages/django/db/models/base.py", line 1119, in _perform_unique_checks
    if qs.exists():
  File "/home/ubuntu/Desktop/venv/lib/python3.6/site-packages/django/db/models/query.py", line 808, in exists
    return self.query.has_results(using=self.db)
  File "/home/ubuntu/Desktop/venv/lib/python3.6/site-packages/django/db/models/sql/query.py", line 550, in has_results
    return compiler.has_results()
  File "/home/ubuntu/Desktop/venv/lib/python3.6/site-packages/django/db/models/sql/compiler.py", line 1145, in has_results
    return bool(self.execute_sql(SINGLE))
  File "/home/ubuntu/Desktop/venv/lib/python3.6/site-packages/django/db/models/sql/compiler.py", line 1175, in execute_sql
    cursor.execute(sql, params)
  File "/home/ubuntu/Desktop/venv/lib/python3.6/site-packages/django/db/backends/utils.py", line 98, in execute
    return super().execute(sql, params)
  File "/home/ubuntu/Desktop/venv/lib/python3.6/site-packages/django/db/backends/utils.py", line 66, in execute
    return self._execute_with_wrappers(sql, params, many=False, executor=self._execute)
  File "/home/ubuntu/Desktop/venv/lib/python3.6/site-packages/django/db/backends/utils.py", line 75, in _execute_with_wrappers
    return executor(sql, params, many, context)
  File "/home/ubuntu/Desktop/venv/lib/python3.6/site-packages/django/db/backends/utils.py", line 84, in _execute
    return self.cursor.execute(sql, params)
  File "/home/ubuntu/Desktop/venv/lib/python3.6/site-packages/django/db/utils.py", line 90, in __exit__
    raise dj_exc_value.with_traceback(traceback) from exc_value
  File "/home/ubuntu/Desktop/venv/lib/python3.6/site-packages/django/db/backends/utils.py", line 84, in _execute
    return self.cursor.execute(sql, params)
  File "/home/ubuntu/Desktop/venv/lib/python3.6/site-packages/django/db/backends/sqlite3/base.py", line 423, in execute
    return Database.Cursor.execute(self, query, params)
django.db.utils.OperationalError: no such table: main_coffee
[pid: 3126|app: 0|req: 10/10] 110.70.58.200 () {52 vars in 1150 bytes} [Mon May 24 23:03:52 2021] POST /admin/main/coffee/add/ => generated 184823 bytes in 83 msecs (HTTP/1.1 500) 6 headers in 187 bytes (1 switches on core 0)
[pid: 3126|app: 0|req: 11/11] 110.70.58.200 () {52 vars in 1150 bytes} [Mon May 24 23:07:31 2021] POST /admin/main/coffee/add/ => generated 0 bytes in 95 msecs (HTTP/1.1 302) 10 headers in 586 bytes (1 switches on core 0)
[pid: 3126|app: 0|req: 12/12] 110.70.58.200 () {46 vars in 1207 bytes} [Mon May 24 23:07:32 2021] GET /admin/main/coffee/ => generated 6260 bytes in 97 msecs (HTTP/1.1 200) 10 headers in 559 bytes (1 switches on core 0)
[pid: 3126|app: 0|req: 13/13] 110.70.58.200 () {42 vars in 777 bytes} [Mon May 24 23:07:32 2021] GET /admin/jsi18n/ => generated 3195 bytes in 17 msecs (HTTP/1.1 200) 6 headers in 189 bytes (1 switches on core 0)
[pid: 3126|app: 0|req: 14/14] 1.225.35.132 () {42 vars in 788 bytes} [Mon May 24 23:07:33 2021] GET /admin/main/coffee/ => generated 0 bytes in 38 msecs (HTTP/1.1 302) 9 headers in 343 bytes (1 switches on core 0)
[pid: 3126|app: 0|req: 15/15] 1.225.35.132 () {40 vars in 786 bytes} [Mon May 24 23:07:34 2021] GET /admin/login/?next=/admin/main/coffee/ => generated 2238 bytes in 43 msecs (HTTP/1.1 200) 9 headers in 461 bytes (1 switches on core 0)
[pid: 3126|app: 0|req: 16/16] 110.70.58.200 () {42 vars in 864 bytes} [Mon May 24 23:07:38 2021] GET / => generated 81025 bytes in 39 msecs (HTTP/1.1 200) 7 headers in 350 bytes (1 switches on core 0)
requw 데이 <QueryDict: {'csrfmiddlewaretoken': ['T8QnTclgHWD6sCATmMJLJsXfxA55P0Iose99u0Y02uSXHE4EqAEqn3WPYvl4JRMq'], 'name': ['2112'], 'price': ['011'], 'cafe_id': ['1'], 'create': ['확인']}>
[pid: 3126|app: 0|req: 17/17] 110.70.58.200 () {52 vars in 1084 bytes} [Mon May 24 23:08:41 2021] POST / => generated 81025 bytes in 43 msecs (HTTP/1.1 200) 7 headers in 350 bytes (1 switches on core 0)
requw 데이 <QueryDict: {'csrfmiddlewaretoken': ['qbujFmRkVK69Bh72F3r02R5SdcTwnnukZhN5gau4gil0QjBNJRmFGs4sE79vheym'], 'name': ['asd'], 'price': ['0'], 'cafe_id': ['0'], 'create': ['확인']}>
[pid: 3126|app: 0|req: 18/18] 110.70.58.200 () {52 vars in 1084 bytes} [Mon May 24 23:08:51 2021] POST / => generated 81129 bytes in 51 msecs (HTTP/1.1 200) 7 headers in 350 bytes (1 switches on core 0)
requw 데이 <QueryDict: {'csrfmiddlewaretoken': ['qbujFmRkVK69Bh72F3r02R5SdcTwnnukZhN5gau4gil0QjBNJRmFGs4sE79vheym'], 'name': ['asd'], 'price': ['0'], 'cafe_id': ['0'], 'create': ['확인']}>
[pid: 3126|app: 0|req: 19/19] 110.70.58.200 () {52 vars in 1084 bytes} [Mon May 24 23:14:22 2021] POST / => generated 81129 bytes in 87 msecs (HTTP/1.1 200) 7 headers in 350 bytes (1 switches on core 0)
*** Starting uWSGI 2.0.19.1 (64bit) on [Tue May 25 00:14:03 2021] ***
compiled with version: 7.5.0 on 24 May 2021 22:26:27
os: Linux-5.4.0-1048-aws #50~18.04.1-Ubuntu SMP Tue May 4 17:40:02 UTC 2021
nodename: ip-172-31-38-43
machine: x86_64
clock source: unix
pcre jit disabled
detected number of CPU cores: 1
current working directory: /home/ubuntu/Desktop/mydjweb
writing pidfile to /tmp/project-master.pid
detected binary path: /home/ubuntu/Desktop/venv/bin/uwsgi
chdir() to /home/ubuntu/Desktop/mydjweb
your processes number limit is 3800
your memory page size is 4096 bytes
detected max file descriptor number: 8192
lock engine: pthread robust mutexes
thunder lock: disabled (you can enable it with --thunder-lock)
uwsgi socket 0 bound to UNIX address /home/ubuntu/Desktop/mydjweb/uwsgi.sock fd 3
Python version: 3.6.9 (default, Jan 26 2021, 15:33:00)  [GCC 8.4.0]
PEP 405 virtualenv detected: /home/ubuntu/Desktop/venv
Set PythonHome to /home/ubuntu/Desktop/venv
*** Python threads support is disabled. You can enable it with --enable-threads ***
Python main interpreter initialized at 0x556808cced20
your server socket listen backlog is limited to 100 connections
your mercy for graceful operations on workers is 60 seconds
mapped 145840 bytes (142 KB) for 1 cores
*** Operational MODE: single process ***
WSGI app 0 (mountpoint='') ready in 1 seconds on interpreter 0x556808cced20 pid: 2883 (default app)
*** uWSGI is running in multiple interpreter mode ***
spawned uWSGI master process (pid: 2883)
spawned uWSGI worker 1 (pid: 2885, cores: 1)
Unnamed: 0     0
country        0
description    0
designation    0
points         0
price          0
province       0
region_1       0
region_2       0
variety        0
winery         0
dtype: int64
Tue May 25 00:14:24 2021 - SIGPIPE: writing to a closed pipe/socket/fd (probably the client disconnected) on request / (ip 110.70.58.200) !!!
Tue May 25 00:14:24 2021 - uwsgi_response_writev_headers_and_body_do(): Broken pipe [core/writer.c line 306] during GET / (110.70.58.200)
OSError: write error
[pid: 2885|app: 0|req: 1/1] 110.70.58.200 () {44 vars in 895 bytes} [Tue May 25 00:14:17 2021] GET / => generated 0 bytes in 6936 msecs (HTTP/1.1 200) 7 headers in 0 bytes (0 switches on core 0)
Tue May 25 00:14:24 2021 - SIGPIPE: writing to a closed pipe/socket/fd (probably the client disconnected) on request / (ip 110.70.58.200) !!!
Tue May 25 00:14:24 2021 - uwsgi_response_writev_headers_and_body_do(): Broken pipe [core/writer.c line 306] during GET / (110.70.58.200)
OSError: write error
[pid: 2885|app: 0|req: 2/2] 110.70.58.200 () {44 vars in 895 bytes} [Tue May 25 00:14:24 2021] GET / => generated 0 bytes in 7 msecs (HTTP/1.1 200) 7 headers in 0 bytes (0 switches on core 0)
[pid: 2885|app: 0|req: 3/3] 110.70.58.200 () {44 vars in 895 bytes} [Tue May 25 00:14:24 2021] GET / => generated 81122 bytes in 7 msecs (HTTP/1.1 200) 7 headers in 350 bytes (1 switches on core 0)
[pid: 2885|app: 0|req: 4/4] 110.70.58.200 () {44 vars in 895 bytes} [Tue May 25 00:14:32 2021] GET / => generated 81122 bytes in 8 msecs (HTTP/1.1 200) 7 headers in 350 bytes (1 switches on core 0)
Tue May 25 00:58:58 2021 - SIGPIPE: writing to a closed pipe/socket/fd (probably the client disconnected) on request / (ip 128.14.209.162) !!!
Tue May 25 00:58:59 2021 - uwsgi_response_writev_headers_and_body_do(): Broken pipe [core/writer.c line 306] during GET / (128.14.209.162)
OSError: write error
[pid: 2885|app: 0|req: 5/5] 128.14.209.162 () {34 vars in 468 bytes} [Tue May 25 00:35:09 2021] GET / => generated 0 bytes in 1432679 msecs (HTTP/1.1 200) 7 headers in 0 bytes (1 switches on core 0)
[pid: 2885|app: 0|req: 6/6] 168.126.77.221 () {40 vars in 711 bytes} [Tue May 25 01:04:14 2021] GET / => generated 81122 bytes in 13633 msecs (HTTP/1.1 200) 7 headers in 350 bytes (1 switches on core 0)
...brutally killing workers...
worker 1 buried after 1 seconds
binary reloading uWSGI...
chdir() to /home/ubuntu/Desktop/mydjweb
closing all non-uwsgi socket fds > 2 (max_fd = 8192)...
found fd 3 mapped to socket 0 (/home/ubuntu/Desktop/mydjweb/uwsgi.sock)
running /home/ubuntu/Desktop/venv/bin/uwsgi
[uWSGI] getting INI configuration from uwsgi.ini
*** Starting uWSGI 2.0.19.1 (64bit) on [Tue May 25 06:41:04 2021] ***
compiled with version: 7.5.0 on 24 May 2021 22:26:27
os: Linux-5.4.0-1048-aws #50~18.04.1-Ubuntu SMP Tue May 4 17:40:02 UTC 2021
nodename: ip-172-31-38-43
machine: x86_64
clock source: unix
pcre jit disabled
detected number of CPU cores: 1
current working directory: /home/ubuntu/Desktop/mydjweb
detected binary path: /home/ubuntu/Desktop/venv/bin/uwsgi
chdir() to /home/ubuntu/Desktop/mydjweb
your processes number limit is 3800
your memory page size is 4096 bytes
detected max file descriptor number: 8192
lock engine: pthread robust mutexes
thunder lock: disabled (you can enable it with --thunder-lock)
uwsgi socket 0 inherited UNIX address /home/ubuntu/Desktop/mydjweb/uwsgi.sock fd 3
Python version: 3.6.9 (default, Jan 26 2021, 15:33:00)  [GCC 8.4.0]
PEP 405 virtualenv detected: /home/ubuntu/Desktop/venv
Set PythonHome to /home/ubuntu/Desktop/venv
*** Python threads support is disabled. You can enable it with --enable-threads ***
Python main interpreter initialized at 0x55ffa9aa6a50
your server socket listen backlog is limited to 100 connections
your mercy for graceful operations on workers is 60 seconds
mapped 145840 bytes (142 KB) for 1 cores
*** Operational MODE: single process ***
WSGI app 0 (mountpoint='') ready in 1 seconds on interpreter 0x55ffa9aa6a50 pid: 2883 (default app)
*** uWSGI is running in multiple interpreter mode ***
gracefully (RE)spawned uWSGI master process (pid: 2883)
spawned uWSGI worker 1 (pid: 5934, cores: 1)
Tue May 25 06:42:33 2021 - uWSGI worker 1 screams: UAAAAAAH my master disconnected: i will kill myself !!!
*** Starting uWSGI 2.0.19.1 (64bit) on [Tue May 25 06:47:03 2021] ***
compiled with version: 7.5.0 on 24 May 2021 22:26:27
os: Linux-5.4.0-1048-aws #50~18.04.1-Ubuntu SMP Tue May 4 17:40:02 UTC 2021
nodename: ip-172-31-38-43
machine: x86_64
clock source: unix
pcre jit disabled
detected number of CPU cores: 1
current working directory: /home/ubuntu/Desktop/mydjweb
writing pidfile to /tmp/project-master.pid
detected binary path: /home/ubuntu/.local/bin/uwsgi
chdir() to /home/ubuntu/Desktop/mydjweb
your processes number limit is 3800
your memory page size is 4096 bytes
detected max file descriptor number: 8192
lock engine: pthread robust mutexes
thunder lock: disabled (you can enable it with --thunder-lock)
uwsgi socket 0 bound to UNIX address /home/ubuntu/Desktop/mydjweb/uwsgi.sock fd 3
Python version: 3.6.9 (default, Jan 26 2021, 15:33:00)  [GCC 8.4.0]
PEP 405 virtualenv detected: /home/ubuntu/Desktop/venv
Set PythonHome to /home/ubuntu/Desktop/venv
*** Python threads support is disabled. You can enable it with --enable-threads ***
Python main interpreter initialized at 0x560be5759c10
your server socket listen backlog is limited to 100 connections
your mercy for graceful operations on workers is 60 seconds
mapped 145840 bytes (142 KB) for 1 cores
*** Operational MODE: single process ***
WSGI app 0 (mountpoint='') ready in 1 seconds on interpreter 0x560be5759c10 pid: 1792 (default app)
*** uWSGI is running in multiple interpreter mode ***
spawned uWSGI master process (pid: 1792)
spawned uWSGI worker 1 (pid: 1796, cores: 1)
Unnamed: 0     0
country        0
description    0
designation    0
points         0
price          0
province       0
region_1       0
region_2       0
variety        0
winery         0
dtype: int64
[pid: 1796|app: 0|req: 1/1] 39.7.58.249 () {44 vars in 893 bytes} [Tue May 25 06:47:16 2021] GET / => generated 81122 bytes in 8163 msecs (HTTP/1.1 200) 7 headers in 350 bytes (1 switches on core 0)
[pid: 1796|app: 0|req: 2/2] 110.137.45.10 () {32 vars in 444 bytes} [Tue May 25 06:54:18 2021] GET / => generated 81122 bytes in 8 msecs (HTTP/1.1 200) 7 headers in 350 bytes (1 switches on core 0)
[pid: 1796|app: 0|req: 3/3] 39.7.58.249 () {42 vars in 862 bytes} [Tue May 25 07:10:20 2021] GET / => generated 81122 bytes in 77 msecs (HTTP/1.1 200) 7 headers in 350 bytes (1 switches on core 0)
[pid: 1796|app: 0|req: 4/4] 39.7.58.249 () {44 vars in 893 bytes} [Tue May 25 07:10:51 2021] GET / => generated 81122 bytes in 20 msecs (HTTP/1.1 200) 7 headers in 350 bytes (1 switches on core 0)
*** Starting uWSGI 2.0.19.1 (64bit) on [Tue May 25 07:12:35 2021] ***
compiled with version: 7.5.0 on 24 May 2021 22:26:27
os: Linux-5.4.0-1048-aws #50~18.04.1-Ubuntu SMP Tue May 4 17:40:02 UTC 2021
nodename: ip-172-31-38-43
machine: x86_64
clock source: unix
pcre jit disabled
detected number of CPU cores: 1
current working directory: /home/ubuntu/Desktop/mydjweb
writing pidfile to /tmp/project-master.pid
detected binary path: /home/ubuntu/.local/bin/uwsgi
chdir() to /home/ubuntu/Desktop/mydjweb
your processes number limit is 3800
your memory page size is 4096 bytes
detected max file descriptor number: 8192
lock engine: pthread robust mutexes
thunder lock: disabled (you can enable it with --thunder-lock)
uwsgi socket 0 bound to UNIX address /home/ubuntu/Desktop/mydjweb/uwsgi.sock fd 3
Python version: 3.6.9 (default, Jan 26 2021, 15:33:00)  [GCC 8.4.0]
PEP 405 virtualenv detected: /home/ubuntu/Desktop/venv
Set PythonHome to /home/ubuntu/Desktop/venv
*** Python threads support is disabled. You can enable it with --enable-threads ***
Python main interpreter initialized at 0x5623eb472c10
your server socket listen backlog is limited to 100 connections
your mercy for graceful operations on workers is 60 seconds
mapped 145840 bytes (142 KB) for 1 cores
*** Operational MODE: single process ***
WSGI app 0 (mountpoint='') ready in 1 seconds on interpreter 0x5623eb472c10 pid: 2235 (default app)
*** uWSGI is running in multiple interpreter mode ***
spawned uWSGI master process (pid: 2235)
spawned uWSGI worker 1 (pid: 2237, cores: 1)
Unnamed: 0     0
country        0
description    0
designation    0
points         0
price          0
province       0
region_1       0
region_2       0
variety        0
winery         0
dtype: int64
[pid: 2237|app: 0|req: 1/1] 39.7.58.249 () {44 vars in 893 bytes} [Tue May 25 07:12:48 2021] GET / => generated 81122 bytes in 8044 msecs (HTTP/1.1 200) 7 headers in 350 bytes (1 switches on core 0)
[pid: 2237|app: 0|req: 2/2] 41.72.214.14 () {32 vars in 449 bytes} [Tue May 25 07:17:01 2021] GET / => generated 81122 bytes in 24 msecs (HTTP/1.1 200) 7 headers in 350 bytes (1 switches on core 0)
Invalid HTTP_HOST header: '_'. The domain name provided is not valid according to RFC 1034/1035.
Bad Request: /
[pid: 2237|app: 0|req: 3/3] 104.152.52.34 () {30 vars in 356 bytes} [Tue May 25 07:17:47 2021] GET / => generated 56790 bytes in 60 msecs (HTTP/1.0 400) 3 headers in 116 bytes (1 switches on core 0)
[pid: 2237|app: 0|req: 4/4] 103.70.144.246 () {32 vars in 444 bytes} [Tue May 25 07:21:47 2021] GET / => generated 81122 bytes in 13 msecs (HTTP/1.1 200) 7 headers in 350 bytes (1 switches on core 0)
*** Starting uWSGI 2.0.19.1 (64bit) on [Tue May 25 08:09:41 2021] ***
compiled with version: 7.5.0 on 24 May 2021 22:26:27
os: Linux-5.4.0-1048-aws #50~18.04.1-Ubuntu SMP Tue May 4 17:40:02 UTC 2021
nodename: ip-172-31-38-43
machine: x86_64
clock source: unix
pcre jit disabled
detected number of CPU cores: 1
current working directory: /etc/uwsgi/vassals
writing pidfile to /tmp/project-master.pid
detected binary path: /home/ubuntu/.local/bin/uwsgi
chdir() to /home/ubuntu/Desktop/mydjweb
your processes number limit is 3800
your memory page size is 4096 bytes
detected max file descriptor number: 8192
lock engine: pthread robust mutexes
thunder lock: disabled (you can enable it with --thunder-lock)
uwsgi socket 0 bound to UNIX address /home/ubuntu/Desktop/mydjweb/uwsgi.sock fd 3
Python version: 3.6.9 (default, Jan 26 2021, 15:33:00)  [GCC 8.4.0]
PEP 405 virtualenv detected: /home/ubuntu/Desktop/venv
Set PythonHome to /home/ubuntu/Desktop/venv
*** Python threads support is disabled. You can enable it with --enable-threads ***
Python main interpreter initialized at 0x55f30f7b08e0
your server socket listen backlog is limited to 100 connections
your mercy for graceful operations on workers is 60 seconds
mapped 145840 bytes (142 KB) for 1 cores
*** Operational MODE: single process ***
WSGI app 0 (mountpoint='') ready in 1 seconds on interpreter 0x55f30f7b08e0 pid: 2554 (default app)
*** uWSGI is running in multiple interpreter mode ***
spawned uWSGI master process (pid: 2554)
spawned uWSGI worker 1 (pid: 2556, cores: 1)
Unnamed: 0     0
country        0
description    0
designation    0
points         0
price          0
province       0
region_1       0
region_2       0
variety        0
winery         0
dtype: int64
[pid: 2556|app: 0|req: 1/1] 39.7.58.249 () {44 vars in 893 bytes} [Tue May 25 08:09:48 2021] GET / => generated 81122 bytes in 9890 msecs (HTTP/1.1 200) 7 headers in 350 bytes (1 switches on core 0)
announcing my loyalty to the Emperor...
SIGINT/SIGQUIT received...killing workers...
Tue May 25 08:10:14 2021 - received message 0 from emperor
worker 1 buried after 1 seconds
goodbye to uWSGI.
VACUUM: pidfile removed.
VACUUM: unix socket /home/ubuntu/Desktop/mydjweb/uwsgi.sock removed.
